<?xml version="1.0"?>
<robot xmlns:xacro="http://www.ros.org/wiki/xacro">

  <!-- Import all Gazebo-customization elements, including Gazebo colors -->
  <xacro:include filename="$(find iiwas_description)/urdf/iiwa.gazebo.xacro" />
  <!-- Import Transmissions -->
  <xacro:include filename="$(find iiwas_description)/urdf/iiwa.transmission.xacro" />
  <!-- Include Utilities -->
  <xacro:include filename="$(find iiwas_description)/urdf/utilities.xacro" />

  <!-- some constants -->
  <xacro:property name="safety_controller_k_pos" value="1" />
  <xacro:property name="safety_controller_k_vel" value="10" />
  <xacro:property name="joint_damping" value="0.5" />

  <xacro:macro name="iiwa14" params="parent hardware_interface robot_name *origin">


    <material name="blue_pastel">
      <color rgba="0.482 0.8 0.894 0.85"/>
    </material>

    <material name="white_clean">
      <color rgba="0.98 0.94 0.84 1."/>
    </material>

    <!--joint between {parent} and link_0-->
    <joint name="${parent}_${robot_name}_base_joint" type="fixed">
      <xacro:insert_block name="origin"/>
      <parent link="${parent}"/>
      <child link="${robot_name}_link_0"/>
    </joint>

    <link name="${robot_name}_link_0">
      <inertial>
        <origin xyz="-0.1 0 0.07" rpy="0 0 0"/>
        <mass value="5"/>
        <inertia ixx="0.05"  ixy="0"  ixz="0" iyy="0.06" iyz="0" izz="0.03" />
      </inertial>

      <visual>
        <origin xyz="0 0 0" rpy="0 0 0"/>
        <geometry>
          <mesh filename="package://iiwas_description/meshes/visual/link_0.stl"/>
        </geometry>
        <material name="white_clean"/>
      </visual>

      <collision>
        <origin xyz="0 0 0" rpy="0 0 0"/>
        <geometry>
          <mesh filename="package://iiwas_description/meshes/collision/link_0.stl"/>
        </geometry>
        <material name="white_clean"/>
      </collision>

      <self_collision_checking>
        <origin xyz="0 0 0" rpy="0 0 0"/>
        <geometry>
          <capsule radius="0.15" length="0.25"/>
        </geometry>
      </self_collision_checking>

    </link>

    <!-- joint between link_0 and link_1 -->
    <joint name="${robot_name}_joint_1" type="revolute">
      <parent link="${robot_name}_link_0"/>
      <child link="${robot_name}_link_1"/>
      <origin xyz="0 0 0.1575" rpy="0 0 0"/>
      <axis xyz="0 0 1"/>
      <limit lower="${-170 * PI / 180}" upper="${170 * PI / 180}"
             effort="320" velocity="${85 * PI / 180}" />
      <safety_controller soft_lower_limit="${-168 * PI / 180}"
                         soft_upper_limit="${168 * PI / 180}"
                         k_position="${safety_controller_k_pos}"
                         k_velocity="${safety_controller_k_vel}"/>
      <dynamics damping="${joint_damping}"/>
    </joint>

    <link name="${robot_name}_link_1">
      <inertial>
        <origin xyz="0 -0.03 0.12" rpy="0 0 0"/>
<!--        <origin xyz="0.003508 -0.001602 0.171113" rpy="0 0 0"/>  &lt;!&ndash; inertial from sl but in different coordinate system &ndash;&gt;-->
        <mass value="3.947808"/>
<!--        <inertia ixx="0.004554"  ixy="0.000001"  ixz="-0.000002" iyy="0.004542" iyz="0.000005" izz="0.000289" />-->
<!--        <inertia ixx="0.4554"  ixy="0.0001"  ixz="-0.0002" iyy="0.4542" iyz="0.0005" izz="0.0289" />-->
        <inertia ixx="0.1"  ixy="0"  ixz="0" iyy="0.09" iyz="0" izz="0.02" />
      </inertial>

      <visual>
        <origin xyz="0 0 0" rpy="0 0 0"/>
        <geometry>
          <mesh filename="package://iiwas_description/meshes/visual/link_1.stl"/>
        </geometry>
        <material name="blue_pastel"/>
      </visual>

      <collision>
        <origin xyz="0 0 0" rpy="0 0 0"/>
        <geometry>
          <mesh filename="package://iiwas_description/meshes/collision/link_1.stl"/>
        </geometry>
        <material name="blue_pastel"/>
      </collision>
    </link>

    <!-- joint between link_1 and link_2 -->
    <joint name="${robot_name}_joint_2" type="revolute">
      <parent link="${robot_name}_link_1"/>
      <child link="${robot_name}_link_2"/>
      <origin xyz="0 0 0.2025" rpy="${PI / 2}   0 ${PI}"/>
      <axis xyz="0 0 1"/>
      <limit lower="${-120 * PI / 180}" upper="${120 * PI / 180}"
             effort="320" velocity="${85 * PI / 180}" />
      <safety_controller soft_lower_limit="${-118 * PI / 180}"
                         soft_upper_limit="${118 * PI / 180}"
                         k_position="${safety_controller_k_pos}"
                         k_velocity="${safety_controller_k_vel}"/>
      <dynamics damping="${joint_damping}"/>
    </joint>

    <link name="${robot_name}_link_2">
      <inertial>
        <origin xyz="0.0003 0.059 0.042" rpy="0 0 0"/>
<!--        <origin xyz="-0.007671 0.166693  -0.003551" rpy="0 0 0"/>  &lt;!&ndash; inertial from sl but in different coordinate system &ndash;&gt;-->
        <mass value="4.502752"/>
<!--        <inertia ixx="0.000318"  ixy="0.000000"  ixz="0.000007" iyy="0.000100" iyz="-0.000003" izz="0.000419" />-->
<!--        <inertia ixx="0.0318"  ixy="0.0000"  ixz="0.0007" iyy="0.0100" iyz="-0.0003" izz="0.0419" />-->
        <inertia ixx="0.05"  ixy="0"  ixz="0" iyy="0.018" iyz="0" izz="0.044" />
      </inertial>
      <visual>
        <origin xyz="0 0 0" rpy="0 0 0"/>
        <geometry>
          <mesh filename="package://iiwas_description/meshes/visual/link_2.stl"/>
        </geometry>
        <material name="blue_pastel"/>
      </visual>

      <collision>
        <origin xyz="0 0 0" rpy="0 0 0"/>
        <geometry>
          <mesh filename="package://iiwas_description/meshes/collision/link_2.stl"/>
        </geometry>
        <material name="blue_pastel"/>
      </collision>
    </link>

    <!-- joint between link_2 and link_3 -->
    <joint name="${robot_name}_joint_3" type="revolute">
      <parent link="${robot_name}_link_2"/>
      <child link="${robot_name}_link_3"/>
      <origin xyz="0 0.2045 0" rpy="${PI / 2} 0 ${PI}"/>
      <axis xyz="0 0 1"/>
      <limit lower="${-170 * PI / 180}" upper="${170 * PI / 180}"
             effort="176" velocity="${100 * PI / 180}" />
      <safety_controller soft_lower_limit="${-168 * PI / 180}"
                         soft_upper_limit="${168 * PI / 180}"
                         k_position="${safety_controller_k_pos}"
                         k_velocity="${safety_controller_k_vel}"/>
      <dynamics damping="${joint_damping}"/>
    </joint>

    <link name="${robot_name}_link_3">
      <inertial>
        <origin xyz="0 0.03 0.13" rpy="0 0 0"/>
<!--        <origin xyz="0.002246 0.034918 0.188978" rpy="0 0 0"/> &lt;!&ndash; inertial from sl but in different coordinate system &ndash;&gt;-->
        <mass value="2.455197"/>
<!--        <inertia ixx="0.002233"  ixy="-0.000046"  ixz="0.000068" iyy="0.002191" iyz="0.000072" izz="0.000725" />-->
<!--        <inertia ixx="0.2233"  ixy="-0.0046"  ixz="0.0068" iyy="0.2191" iyz="0.0072" izz="0.0725" />-->
        <inertia ixx="0.08"  ixy="0"  ixz="0" iyy="0.075" iyz="0" izz="0.01" />
      </inertial>

      <visual>
        <origin xyz="0 0 0" rpy="0 0 0"/>
        <geometry>
          <mesh filename="package://iiwas_description/meshes/visual/link_3.stl"/>
        </geometry>
        <material name="blue_pastel"/>
      </visual>

      <collision>
        <origin xyz="0 0 0" rpy="0 0 0"/>
        <geometry>
          <mesh filename="package://iiwas_description/meshes/collision/link_3.stl"/>
        </geometry>
        <material name="blue_pastel"/>
      </collision>
    </link>

    <!-- joint between link_3 and link_4 -->
    <joint name="${robot_name}_joint_4" type="revolute">
      <parent link="${robot_name}_link_3"/>
      <child link="${robot_name}_link_4"/>
      <origin xyz="0 0 0.2155" rpy="${PI / 2} 0 0"/>
      <axis xyz="0 0 1"/>
      <limit lower="${-120 * PI / 180}" upper="${120 * PI / 180}"
             effort="176" velocity="${75 * PI / 180}" />
      <safety_controller soft_lower_limit="${-118 * PI / 180}"
                         soft_upper_limit="${118 * PI / 180}"
                         k_position="${safety_controller_k_pos}"
                         k_velocity="${safety_controller_k_vel}"/>
      <dynamics damping="${joint_damping}"/>
    </joint>

    <link name="${robot_name}_link_4">
      <inertial>
        <origin xyz="0 0.067 0.034" rpy="0 0 0"/>
<!--        <origin xyz="-0.000196  0.052679 0.038182" rpy="0 0 0"/> &lt;!&ndash; inertial from sl but in different coordinate system &ndash;&gt;-->
        <mass value="2.611550"/>
<!--        <inertia ixx="0.038444"  ixy="0.000880"  ixz="-0.001120" iyy="0.011437" iyz="-0.001113" izz=" 0.049880" />-->
<!--        <inertia ixx="3.8444"  ixy="0.0880"  ixz="-0.1120" iyy="1.1437" iyz="-0.1113" izz=" 4.9880" />-->
        <inertia ixx="0.03"  ixy="0"  ixz="0" iyy="0.01" iyz="0" izz="0.029" />
      </inertial>

      <visual>
        <origin xyz="0 0 0" rpy="0 0 0"/>
        <geometry>
          <mesh filename="package://iiwas_description/meshes/visual/link_4.stl"/>
        </geometry>
        <material name="blue_pastel"/>
      </visual>

      <collision>
        <origin xyz="0 0 0" rpy="0 0 0"/>
        <geometry>
          <mesh filename="package://iiwas_description/meshes/collision/link_4.stl"/>
        </geometry>
        <material name="blue_pastel"/>
      </collision>
    </link>

    <!-- joint between link_4 and link_5 -->
    <joint name="${robot_name}_joint_5" type="revolute">
      <parent link="${robot_name}_link_4"/>
      <child link="${robot_name}_link_5"/>
      <origin xyz="0 0.1845 0" rpy="${-PI / 2} ${PI} 0"/>
      <axis xyz="0 0 1"/>
      <limit lower="${-170 * PI / 180}" upper="${170 * PI / 180}"
             effort="110" velocity="${130 * PI / 180}" />
      <safety_controller soft_lower_limit="${-168 * PI / 180}"
                         soft_upper_limit="${168 * PI / 180}"
                         k_position="${safety_controller_k_pos}"
                         k_velocity="${safety_controller_k_vel}"/>
      <dynamics damping="${joint_damping}"/>
    </joint>

    <link name="${robot_name}_link_5">
      <inertial>
        <origin xyz="0.0001 0.021 0.076" rpy="0 0 0"/>
<!--        <origin xyz="0.000054  -0.002367 0.004164" rpy="0 0 0"/> &lt;!&ndash; inertial from sl but in different coordinate system &ndash;&gt;-->
        <mass value="3.410009"/>
<!--        <inertia ixx="0.002769"  ixy="-0.000008"  ixz="0.000006" iyy="0.002842" iyz="-0.000001" izz="0.000117" />-->
<!--        <inertia ixx="0.2769"  ixy="-0.0008"  ixz="0.0006" iyy="0.2842" iyz="-0.0001" izz="0.0117" />-->
        <inertia ixx="0.02"  ixy="0"  ixz="0" iyy="0.018" iyz="0" izz="0.005" />
      </inertial>

      <visual>
        <origin xyz="0 0 0" rpy="0 0 0"/>
        <geometry>
          <mesh filename="package://iiwas_description/meshes/visual/link_5.stl"/>
        </geometry>
        <material name="blue_pastel"/>
      </visual>

      <collision>
        <origin xyz="0 0 0" rpy="0 0 0"/>
        <geometry>
          <mesh filename="package://iiwas_description/meshes/collision/link_5.stl"/>
        </geometry>
        <material name="blue_pastel"/>
      </collision>
    </link>

    <!-- joint between link_5 and link_6 -->
    <joint name="${robot_name}_joint_6" type="revolute">
      <parent link="${robot_name}_link_5"/>
      <child link="${robot_name}_link_6"/>
      <origin xyz="0 0 0.2155" rpy="${PI / 2} 0 0"/>
      <axis xyz="0 0 1"/>
      <limit lower="${-120 * PI / 180}" upper="${120 * PI / 180}"
             effort="40" velocity="${135 * PI / 180}" />
      <safety_controller soft_lower_limit="${-118 * PI / 180}"
                         soft_upper_limit="${118 * PI / 180}"
                         k_position="${safety_controller_k_pos}"
                         k_velocity="${safety_controller_k_vel}"/>
      <dynamics damping="${joint_damping}"/>
    </joint>

    <link name="${robot_name}_link_6">
      <inertial>
        <origin xyz="0 0.0006 0.0004" rpy="0 0 0"/>
<!--        <origin xyz="0.000492  0.020190  -0.027496" rpy="0 0 0"/>   &lt;!&ndash; inertial from sl but in different coordinate system &ndash;&gt;-->
        <mass value="3.387949"/>
<!--        <inertia ixx="0.000500"  ixy="-0.000050"  ixz="-0.000024" iyy="0.002809" iyz="-0.000041" izz="0.002315" />-->
<!--        <inertia ixx="0.0500"  ixy="-0.0050"  ixz="-0.0024" iyy="0.2809" iyz="-0.0041" izz="0.2315" />-->
        <inertia ixx="0.005"  ixy="0"  ixz="0" iyy="0.0036" iyz="0" izz="0.0047" />
      </inertial>

      <visual>
        <origin xyz="0 0 0" rpy="0 0 0"/>
        <geometry>
          <mesh filename="package://iiwas_description/meshes/visual/link_6.stl"/>
        </geometry>
        <material name="blue_pastel"/>
      </visual>

      <collision>
        <origin xyz="0 0 0" rpy="0 0 0"/>
        <geometry>
          <mesh filename="package://iiwas_description/meshes/collision/link_6.stl"/>
        </geometry>
        <material name="blue_pastel"/>
      </collision>
    </link>

    <!-- joint between link_6 and link_7 -->
    <joint name="${robot_name}_joint_7" type="revolute">
      <parent link="${robot_name}_link_6"/>
      <child link="${robot_name}_link_7"/>
      <origin xyz="0 0.081 0" rpy="${- PI / 2} ${PI} 0"/>
      <axis xyz="0 0 1"/>
      <limit lower="${-175 * PI / 180}" upper="${175 * PI / 180}"
             effort="40" velocity="${135 * PI / 180}" />
      <safety_controller soft_lower_limit="${-173 * PI / 180}"
                         soft_upper_limit="${173 * PI / 180}"
                         k_position="${safety_controller_k_pos}"
                         k_velocity="${safety_controller_k_vel}"/>
      <dynamics damping="${joint_damping}"/>
    </joint>

    <link name="${robot_name}_link_7">
      <inertial>
        <origin xyz="0 0 0.02" rpy="0 0 0"/>
<!--        <origin xyz="0.034656 0.023242 -0.009623" rpy="0 0 0"/> &lt;!&ndash; inertial from sl but in different coordinate system &ndash;&gt;-->
        <mass value="0.354321"/>
<!--        <inertia ixx="0.007946"  ixy="0.000221"  ixz="-0.000294" iyy=" 0.010889" iyz="-0.000294" izz="0.002944" />-->
<!--        <inertia ixx="0.7946"  ixy="0.0221"  ixz="-0.0294" iyy=" 1.0889" iyz="-0.0294" izz="0.2944" />-->
        <inertia ixx="0.001"  ixy="0"  ixz="0" iyy="0.001" iyz="0" izz="0.001" />
      </inertial>

      <visual>
        <origin xyz="0 0 0" rpy="0 0 0"/>
        <geometry>
          <mesh filename="package://iiwas_description/meshes/visual/link_7.stl"/>
        </geometry>
        <material name="white_clean"/>
      </visual>

      <collision>
        <origin xyz="0 0 0" rpy="0 0 0"/>
        <geometry>
          <mesh filename="package://iiwas_description/meshes/collision/link_7.stl"/>
        </geometry>
        <material name="white_clean"/>
      </collision>
    </link>

    <joint name="${robot_name}_SAKE" type="fixed">
      <parent link="${robot_name}_link_7"/>
      <child link="${robot_name}_link_ee"/>
      <origin xyz="0 0 0.07" rpy="0 0 0"/>
    </joint>

    <link name="${robot_name}_link_ee">
      <inertial>
      <origin rpy="0 0 0" xyz="0 0 0.0"/>
      <mass value="0.0"/>
      <inertia ixx="0.0" ixy="0.0" ixz="0.0" iyy="0.0" iyz="0.0" izz="0.0"/>
    </inertial>
    </link>

    <!--Extensions -->
    <xacro:iiwa_gazebo robot_name="${robot_name}" />
    <xacro:iiwa_transmission robot_name="${robot_name}" hardware_interface="${hardware_interface}"/>

  </xacro:macro>

</robot>
